<?xml version="1.0" ?>
<robot name="robot_xacro" xmlns:xacro="https://www.ros.org/wiki/xacro" >
    
 <xacro:include filename="$(find exprob_3)/urdf/robot.gazebo" />
 
  <material name="black">
    <color rgba="0.0 0.0 0.0 1.0"/>
  </material>
  <material name="blue">
    <color rgba="0.203125 0.23828125 0.28515625 1.0"/>
  </material>
  <material name="green">
    <color rgba="0.0 0.8 0.0 1.0"/>
  </material>
  <material name="grey">
    <color rgba="0.2 0.2 0.2 1.0"/>
  </material>
  <material name="orange">
    <color rgba="1.0 0.423529411765 0.0392156862745 1.0"/>
  </material>
  <material name="brown">
    <color rgba="0.870588235294 0.811764705882 0.764705882353 1.0"/>
  </material>
  <material name="red">
    <color rgba="0.80078125 0.12890625 0.1328125 1.0"/>
  </material>
  <material name="white">
    <color rgba="1.0 1.0 1.0 1.0"/>
  </material>  
 
 <xacro:macro name="cylinder_inertia" params="mass r l"> 
    <inertia ixx="${mass*(3*r*r+l*l)/12}" ixy = "0" ixz = "0"
                iyy="${mass*(3*r*r+l*l)/12}" iyz = "0" izz="${mass*(r*r)/2}" /> 
 </xacro:macro>

    <xacro:macro name="link_wheel" params="name">
        <link name="${name}">
            <inertial>
              <mass value="0.2"/>
              <origin rpy="0 1.5707 1.5707" xyz="0 0 0"/>
              <inertia ixx="0.000526666666667" ixy="0" ixz="0" iyy="0.000526666666667" iyz="0" izz="0.001"/>
            </inertial>
            <collision name="link_right_wheel_collision">
              <origin rpy="0 1.5707 1.5707" xyz="0 0 0"/>
              <geometry>
                <cylinder length="0.04" radius="0.1"/>
              </geometry>
            </collision>
            <visual name="${name}_visual">
              <origin rpy="0 1.5707 1.5707" xyz="0 0 0"/>
              <geometry>
                <cylinder length="0.04" radius="0.1"/>
              </geometry>
            </visual>
        </link>
    </xacro:macro>
 
     <xacro:macro name="joint_wheel" params="name child origin_xyz">
      <joint name="${name}" type="continuous">
        <origin rpy="0 0 0" xyz="${origin_xyz}"/>
        <child link="${child}"/>
        <parent link="link_chassis"/>
        <axis rpy="0 0 0" xyz="0 1 0"/>
        <limit effort="10000" velocity="1000"/>
        <joint_properties damping="1.0" friction="1.0"/>
      </joint>
    </xacro:macro>


  
  <link name="link_chassis">
    <!-- pose and inertial -->
    <pose>0 0 0.1 0 0 0</pose>
    
    <inertial>
      <mass value="5"/>
      <origin rpy="0 0 0" xyz="0 0 0.1"/>
      <inertia ixx="0.0395416666667" ixy="0" ixz="0" iyy="0.106208333333" iyz="0" izz="0.106208333333"/>
    </inertial>
    
    <collision name="collision_chassis">
      <geometry>
        <box size="0.5 0.3 0.07"/>
      </geometry>
    </collision>
    
    <visual>
      <origin rpy="0 0 0" xyz="0 0 0"/>
      <geometry>
        <box size="0.5 0.3 0.07"/>
      </geometry>
      <material name="blue"/>
    </visual>
    
    <!-- caster front -->
    <collision name="caster_front_collision">
      <origin rpy=" 0 0 0" xyz="0.35 0 -0.05"/>
      <geometry>
        <sphere radius="0.05"/>
      </geometry>
      <surface>
        <friction>
          <ode>
            <mu>0</mu>
            <mu2>0</mu2>
            <slip1>1.0</slip1>
            <slip2>1.0</slip2>
          </ode>
        </friction>
      </surface>
    </collision>
    <visual name="caster_front_visual">
      <origin rpy=" 0 0 0" xyz="0.2 0 -0.05"/>
      <geometry>
        <sphere radius="0.05"/>
      </geometry>
    </visual>
    </link>
  
  <!-- Create wheels -->  

  <xacro:link_wheel name="link_right_wheel" />
  <xacro:link_wheel name="link_left_wheel" />
  <xacro:joint_wheel name="joint_right_wheel"  child="link_right_wheel"  origin_xyz="-0.05 0.15 0"  />
  <xacro:joint_wheel name="joint_left_wheel"   child="link_left_wheel"   origin_xyz="-0.05 -0.15 0"  />


   <link name="hokuyo_link">
	    <collision>
	      <origin xyz="0 0 0.025" rpy="0 0 0"/>
	      <geometry>
		<box size="0.05 0.05 0.05"/>
	      </geometry>
	    </collision>
	    <visual>
	      <origin xyz="0 0 0.025" rpy="0 0 0"/>
	      <geometry>
		<box size="0.05 0.05 0.05"/>
	      </geometry>
	      <material name="red">
		<color rgba="1 0 0 1"/>
	      </material>
	    </visual>
	    <inertial>
	      <mass value="1e-5" />
	      <origin xyz="0 0 0" rpy="0 0 0"/>
	      <inertia ixx="1e-6" ixy="0" ixz="0" iyy="1e-6" iyz="0" izz="1e-6" />
	    </inertial> 
  </link>
  
  <joint name="hokuyo_joint" type="fixed">
	    <axis xyz="0 1 0" />
	    <origin xyz="0.28 0 0.05" rpy="0 0 0"/>
	    <parent link="link_chassis"/>
	    <child link="hokuyo_link"/> 
 </joint>

<!--arm definition -->

  <link name="arm_base_link">
  	<inertial>
  		<mass value="0.1"/>
  		<origin xyz="0 0 0" rpy="0 0 0" />
  		<inertia ixx="0.0000416666667" ixy="0" ixz="0" iyy="0.0000416666667" iyz="0" izz="0.0000416666667"/>
  	</inertial>
  	<collision>
  	  <origin xyz="0 0 0" rpy="0 0 0"/>
      <geometry>
        <box size="0.1 0.1 0.1"/>
      </geometry>
  	</collision>
  	<visual>
  	  <origin xyz="0 0 0" rpy="0 0 0"/>
      <geometry>
        <box size="0.1 0.1 0.1"/>
      </geometry>
      <material name="red" />
  	</visual>
  </link>

  <joint name="arm_base_to_base" type="fixed">
  	<origin rpy="0 0 0" xyz="0 0 0.085"/>
  	<parent link="link_chassis"/>
  	<child link="arm_base_link"/>
  </joint>


  <link name="arm_link_01">
  	<inertial>
  		<mass value="0.025"/>
  		<origin xyz="0 0 0" rpy="0 0 0" />
  		<inertia ixx="0.000010279" ixy="0" ixz="0" iyy="0.000010279" iyz="0" izz="0.000007225"/>
  	</inertial>
  	<collision>
  	  <origin xyz="0 0 0.3" rpy="0 0 0"/>
      <geometry>
        <cylinder radius="0.04" length="0.8"/>
      </geometry>
  	</collision>
  	<visual>
  	  <origin xyz="0 0 0.3" rpy="0 0 0"/>
      <geometry>
        <cylinder radius="0.04" length="0.8"/>
      </geometry>
      <material name="red" />
  	</visual>
  </link>

  <joint name="arm_joint_01" type="revolute">
  	<axis xyz="0 0 1"/>
  	<limit effort="1000.0" lower="-3.14" upper="3.14" velocity="0.2"/>
  	<origin rpy="0 0 0" xyz="0 0 0"/>
  	<parent link="arm_base_link"/>
  	<child link="arm_link_01"/>
  </joint>


    <link name="arm_link_02">
  	<inertial>
  		<mass value="0.025"/>
  		<origin xyz="0 0 0" rpy="0 0 0" />
  		<inertia ixx="0.000010279" ixy="0" ixz="0" iyy="0.000010279" iyz="0" izz="0.000007225"/>
  	</inertial>
  	<collision>
  	  <origin xyz="0.32 0 -0.22" rpy="0 1.5708 0"/>
      <geometry>
        <cylinder radius="0.04" length="0.7"/>
      </geometry>
  	</collision>
  	<visual>
  	  <origin xyz="0.32 0 -0.22" rpy="0 1.5708 0"/>
      <geometry>
        <cylinder radius="0.04" length="0.7"/>
      </geometry>
      <material name="red" />
  	</visual>
  </link>

  <joint name="arm_joint_02" type="revolute">
  	<axis xyz="1 0 0"/>
  	<limit effort="1000.0" lower="-1.8" upper="1.8" velocity="0.2"/>
  	<origin rpy="0 0 0" xyz="0 0 0.5"/>
  	<parent link="arm_link_01"/>
  	<child link="arm_link_02"/>
  </joint>
  
  
  
   <link name="camera_link">
	    <collision>
	      <origin xyz="0 0 0.025" rpy="0 0 0"/>
	      <geometry>
		<box size="0.05 0.05 0.05"/>
	      </geometry>
	    </collision>
	    <visual>
	      <origin xyz="0 0 0.025" rpy="0 0 0"/>
	      <geometry>
		<box size="0.05 0.05 0.05"/>
	      </geometry>
	      <material name="red">
		<color rgba="1 0 0 1"/>
	      </material>
	    </visual>
	    <inertial>
	      <mass value="1e-5" />
	      <origin xyz="0 0 0" rpy="0 0 0"/>
	      <inertia ixx="1e-6" ixy="0" ixz="0" iyy="1e-6" iyz="0" izz="1e-6" />
	    </inertial> 
  </link>
  
  <joint name="camera_joint" type="fixed">
	    <axis xyz="0 1 0" />
	    <origin xyz="0.23 0 0.0" rpy="0 0 0"/>
	    <parent link="link_chassis"/>
	    <child link="camera_link"/> 
	 </joint>

<gazebo reference="camera_link">
    <sensor type="camera" name="camera">
      <update_rate>30.0</update_rate>
      <camera name="head">
        <horizontal_fov>1.3962634</horizontal_fov>
        <image>
          <width>800</width>
          <height>800</height>
          <format>R8G8B8</format>
        </image>
        <clip>
          <near>0.02</near>
          <far>300</far>
        </clip>
		<noise>
          <type>gaussian</type>
          <mean>0.0</mean>
          <stddev>0.007</stddev>
        </noise>
      </camera>
      <plugin name="camera_controller" filename="libgazebo_ros_camera.so">
        <alwaysOn>true</alwaysOn>
        <updateRate>0.0</updateRate>
        <cameraName>camera1</cameraName>
        <imageTopicName>image_raw</imageTopicName>
        <cameraInfoTopicName>camera_info</cameraInfoTopicName>
        <frameName>camera_link</frameName>
        <hackBaseline>0.07</hackBaseline>
        <distortionK1>0.0</distortionK1>
        <distortionK2>0.0</distortionK2>
        <distortionK3>0.0</distortionK3>
        <distortionT1>0.0</distortionT1>
        <distortionT2>0.0</distortionT2>
      </plugin>
    </sensor>
  </gazebo> 


</robot>
